Workbook

Sheet Dashboard
B1: SNEH BUILDCON PVT. LTD.
B2: DATE : | E2: =IF(OR(G2="",G2="Latest"),MAX('Daily Boulder'!$A$5:$A$800),IF(ISNUMBER(G2),G2,IFERROR(DATEVALUE(G2),MAX('Daily Boulder'!$A$5:$A$800)))) | G2: Latest
B3: CRUSHER PLANT PRODUCTION & DISPATCH REPORT | G3: ▲ tap to choose day
B4: TOGETHER WE BUILD | TOGETHER WE GROW | TOGETHER WE CREATE
B6: 1. BOULDER RECEIPT & CRUSHING | F6: 2. TODAY'S DISPATCH
B7: Particular | C7: Quantity (MT) | D7: Trips | F7: Material | G7: Quantity (MT) | H7: Trips
B8: Total Boulder Received at Crusher | C8: =IFERROR(INDEX('Daily Boulder'!$B$5:$B$800,MATCH(Dashboard!$E$2,'Daily Boulder'!$A$5:$A$800,0)),"") | D8: =IFERROR(INDEX('Daily Boulder'!$J$5:$J$800,MATCH(Dashboard!$E$2,'Daily Boulder'!$A$5:$A$800,0)),"") | F8: 10 MM Aggregate | G8: =IFERROR(INDEX('Daily Dispatch'!$B$5:$B$800,MATCH(Dashboard!$E$2,'Daily Dispatch'!$A$5:$A$800,0)),"") | H8: =IFERROR(INDEX('Daily Dispatch'!$C$5:$C$800,MATCH(Dashboard!$E$2,'Daily Dispatch'!$A$5:$A$800,0)),"")
B9: Boulder Received at Crusher Hopper | C9: =IFERROR(INDEX('Daily Boulder'!$D$5:$D$800,MATCH(Dashboard!$E$2,'Daily Boulder'!$A$5:$A$800,0)),"") | D9: =IFERROR(INDEX('Daily Boulder'!$K$5:$K$800,MATCH(Dashboard!$E$2,'Daily Boulder'!$A$5:$A$800,0)),"") | F9: 20 MM Aggregate | G9: =IFERROR(INDEX('Daily Dispatch'!$D$5:$D$800,MATCH(Dashboard!$E$2,'Daily Dispatch'!$A$5:$A$800,0)),"") | H9: =IFERROR(INDEX('Daily Dispatch'!$E$5:$E$800,MATCH(Dashboard!$E$2,'Daily Dispatch'!$A$5:$A$800,0)),"")
B10: Boulder Received at Crusher Stock | C10: =IFERROR(INDEX('Daily Boulder'!$L$5:$L$800,MATCH(Dashboard!$E$2,'Daily Boulder'!$A$5:$A$800,0)),"") | D10: =IFERROR(INDEX('Daily Boulder'!$M$5:$M$800,MATCH(Dashboard!$E$2,'Daily Boulder'!$A$5:$A$800,0)),"") | F10: 30 MM Aggregate | G10: =IFERROR(INDEX('Daily Dispatch'!$F$5:$F$800,MATCH(Dashboard!$E$2,'Daily Dispatch'!$A$5:$A$800,0)),"") | H10: =IFERROR(INDEX('Daily Dispatch'!$G$5:$G$800,MATCH(Dashboard!$E$2,'Daily Dispatch'!$A$5:$A$800,0)),"")
B11: Stock Boulder Up to Date | C11: =IFERROR(INDEX('Daily Boulder'!$R$5:$R$800,MATCH(Dashboard!$E$2,'Daily Boulder'!$A$5:$A$800,0)),"") | D11: Daily | F11: M-Sand | G11: =IFERROR(INDEX('Daily Dispatch'!$H$5:$H$800,MATCH(Dashboard!$E$2,'Daily Dispatch'!$A$5:$A$800,0)),"") | H11: =IFERROR(INDEX('Daily Dispatch'!$I$5:$I$800,MATCH(Dashboard!$E$2,'Daily Dispatch'!$A$5:$A$800,0)),"")
B12: Boulder Crushing from Stock | C12: =IFERROR(INDEX('Daily Boulder'!$F$5:$F$800,MATCH(Dashboard!$E$2,'Daily Boulder'!$A$5:$A$800,0)),"") | D12: =IFERROR(INDEX('Daily Boulder'!$N$5:$N$800,MATCH(Dashboard!$E$2,'Daily Boulder'!$A$5:$A$800,0)),"") | F12: Total Aggregate Dispatch | G12: =IFERROR(INDEX('Daily Dispatch'!$J$5:$J$800,MATCH(Dashboard!$E$2,'Daily Dispatch'!$A$5:$A$800,0)),"") | H12: =IFERROR(INDEX('Daily Dispatch'!$K$5:$K$800,MATCH(Dashboard!$E$2,'Daily Dispatch'!$A$5:$A$800,0)),"")
B13: Total Boulder Crushing Today | C13: =IFERROR(INDEX('Daily Boulder'!$O$5:$O$800,MATCH(Dashboard!$E$2,'Daily Boulder'!$A$5:$A$800,0)),"") | D13: =IFERROR(INDEX('Daily Boulder'!$P$5:$P$800,MATCH(Dashboard!$E$2,'Daily Boulder'!$A$5:$A$800,0)),"") | F13: Total Dispatch – All Material | G13: =IFERROR(INDEX('Daily Dispatch'!$L$5:$L$800,MATCH(Dashboard!$E$2,'Daily Dispatch'!$A$5:$A$800,0)),"") | H13: =IFERROR(INDEX('Daily Dispatch'!$M$5:$M$800,MATCH(Dashboard!$E$2,'Daily Dispatch'!$A$5:$A$800,0)),"")
B14: ="Note: • Boulder crushing from stock is based on an average of "&TEXT(IFERROR(INDEX('Daily Boulder'!$X$5:$X$800,MATCH(Dashboard!$E$2,'Daily Boulder'!$A$5:$A$800,0)),Settings!$B$5),"0")&" MT per vehicle."
B15: ="• Boulder received at crusher stock is based on today's average of "&TEXT(IFERROR(INDEX('Daily Boulder'!$Y$5:$Y$800,MATCH(Dashboard!$E$2,'Daily Boulder'!$A$5:$A$800,0)),Settings!$B$5),"0.0")&" MT per vehicle." | F15: 3. MONTHLY DISPATCH STATUS
B16: Boulder Received at Crusher – This Month | C16: =IFERROR(INDEX('Daily Boulder'!$T$5:$T$800,MATCH(Dashboard!$E$2,'Daily Boulder'!$A$5:$A$800,0)),"") | D16: =IFERROR(INDEX('Daily Boulder'!$U$5:$U$800,MATCH(Dashboard!$E$2,'Daily Boulder'!$A$5:$A$800,0)),"") | F16: Particular | G16: Quantity (MT) | H16: Trips
B17: Total Cumulative Production Up to Date | C17: =IFERROR(INDEX('Daily Boulder'!$V$5:$V$800,MATCH(Dashboard!$E$2,'Daily Boulder'!$A$5:$A$800,0)),"") | D17: =IFERROR(INDEX('Daily Boulder'!$W$5:$W$800,MATCH(Dashboard!$E$2,'Daily Boulder'!$A$5:$A$800,0)),"") | F17: Total Aggregate Dispatch – This Month | G17: =IFERROR(INDEX('Daily Dispatch'!$N$5:$N$800,MATCH(Dashboard!$E$2,'Daily Dispatch'!$A$5:$A$800,0)),"") | H17: =IFERROR(INDEX('Daily Dispatch'!$O$5:$O$800,MATCH(Dashboard!$E$2,'Daily Dispatch'!$A$5:$A$800,0)),"")
F18: Total M-Sand Dispatch – This Month | G18: =IFERROR(INDEX('Daily Dispatch'!$P$5:$P$800,MATCH(Dashboard!$E$2,'Daily Dispatch'!$A$5:$A$800,0)),"") | H18: =IFERROR(INDEX('Daily Dispatch'!$Q$5:$Q$800,MATCH(Dashboard!$E$2,'Daily Dispatch'!$A$5:$A$800,0)),"")
F19: Total Dispatch – All Material This Month | G19: =IFERROR(INDEX('Daily Dispatch'!$R$5:$R$800,MATCH(Dashboard!$E$2,'Daily Dispatch'!$A$5:$A$800,0)),"") | H19: =IFERROR(INDEX('Daily Dispatch'!$S$5:$S$800,MATCH(Dashboard!$E$2,'Daily Dispatch'!$A$5:$A$800,0)),"")
B21: 4. PLANT AND EQUIPMENT'S RUNNING HOURS/KM | F21: 6. REMARKS
B22: Section / Equipment | C22: Running Hours / KM | F22: Primary Section :
B23: Primary Section | C23: =IFERROR(INDEX('Hours & Remarks'!$B$5:$B$800,MATCH(Dashboard!$E$2,'Hours & Remarks'!$A$5:$A$800,0)),"") | F23: =IFERROR(INDEX('Hours & Remarks'!$F$5:$F$800,MATCH(Dashboard!$E$2,'Hours & Remarks'!$A$5:$A$800,0))&"","")
B24: Secondary Section | C24: =IFERROR(INDEX('Hours & Remarks'!$C$5:$C$800,MATCH(Dashboard!$E$2,'Hours & Remarks'!$A$5:$A$800,0)),"")
B25: Hyundai Excavator R230 | C25: =IFERROR(INDEX('Hours & Remarks'!$D$5:$D$800,MATCH(Dashboard!$E$2,'Hours & Remarks'!$A$5:$A$800,0)),"") | F25: Secondary Section :
B26: JCB UP92T7813 | C26: =IFERROR(INDEX('Hours & Remarks'!$E$5:$E$800,MATCH(Dashboard!$E$2,'Hours & Remarks'!$A$5:$A$800,0)),"") | F26: =IFERROR(INDEX('Hours & Remarks'!$G$5:$G$800,MATCH(Dashboard!$E$2,'Hours & Remarks'!$A$5:$A$800,0))&"","")
B27: Camper MP07ZM6345 | C27: =IFERROR(INDEX('Hours & Remarks'!$H$5:$H$800,MATCH(Dashboard!$E$2,'Hours & Remarks'!$A$5:$A$800,0)),"")
B29: 5. FUEL (DIESEL)
B30: Equipment / Vehicle | C30: Diesel Received Today | F30: Total Diesel Consumption This Month
B31: Camper MP07ZM6345 | C31: =IFERROR(INDEX('Diesel'!$B$5:$B$800,MATCH(Dashboard!$E$2,'Diesel'!$A$5:$A$800,0)),"") | F31: =IFERROR(INDEX('Diesel'!$F$5:$F$800,MATCH(Dashboard!$E$2,'Diesel'!$A$5:$A$800,0)),"")
B32: JCB UP92T7813 | C32: =IFERROR(INDEX('Diesel'!$C$5:$C$800,MATCH(Dashboard!$E$2,'Diesel'!$A$5:$A$800,0)),"")
B33: Hyundai Excavator R230 | C33: =IFERROR(INDEX('Diesel'!$D$5:$D$800,MATCH(Dashboard!$E$2,'Diesel'!$A$5:$A$800,0)),"")
B34: Diesel Received Today (Total) | C34: =IFERROR(INDEX('Diesel'!$E$5:$E$800,MATCH(Dashboard!$E$2,'Diesel'!$A$5:$A$800,0)),"")
F36: ="Prepared by: "&Settings!$B$15
B38: DASHBOARD – LAST 15 DAYS (ending on the report date)

Sheet Daily Boulder
A1: BLOCK 1 – BOULDER RECEIPT, STOCK & CRUSHING (one row per day)
A2: Yellow = you type. Trips and Physical stock are OPTIONAL: leave trips blank to calculate MT ÷ avg; type physical stock only when the real stock differs from the calculated (book) stock.
B3: YOU TYPE | I3: CALCULATED | T3: MONTH & CUMULATIVE | X3: REPORT NOTE
A4: Date | B4: Total Received at Crusher MT | C4: Received Trips (optional) | D4: Direct to Hopper MT | E4: Hopper Trips (optional) | F4: Crushed from Stock MT | G4: From-Stock Trips (optional) | H4: Physical Closing Stock (optional) MT | I4: Opening Stock (prev day closing) MT | J4: Received Trips | K4: Hopper Trips | L4: Went to Stock MT | M4: Stock Trips | N4: From-Stock Trips | O4: Total Crushing Today MT | P4: Total Crushing Trips | Q4: Book Closing Stock MT | R4: Closing Stock (Stock up to date) MT | S4: Physical − Book Difference MT | T4: Received This Month MT | U4: Received This Month Trips | V4: Cumulative Production MT | W4: Cumulative Production Trips | X4: Note avg from stock MT/vehicle | Y4: Note avg at stock MT/vehicle
I5: =IF($A5="","",Settings!$B$4) | J5: =IF($A5="","",IF(C5="",0,C5)) | K5: =IF($A5="","",IF(E5="",0,E5)) | L5: =IF($A5="","",B5-D5) | M5: =IF($A5="","",J5-K5) | N5: =IF($A5="","",IF(G5="",0,G5)) | O5: =IF($A5="","",D5+F5) | P5: =IF($A5="","",K5+N5) | Q5: =IF($A5="","",I5+L5-F5) | R5: =IF($A5="","",IF(H5="",Q5,H5)) | S5: =IF($A5="","",R5-Q5) | T5: =IF($A5="","",SUMIFS($B$5:$B$800,$A$5:$A$800,">="&DATE(YEAR($A5),MONTH($A5),1),$A$5:$A$800,"<="&$A5)+IF(AND(YEAR($A5)=YEAR(Settings!$B$3),MONTH($A5)=MONTH(Settings!$B$3)),Settings!$B$6,0)) | U5: =IF($A5="","",SUMIFS($J$5:$J$800,$A$5:$A$800,">="&DATE(YEAR($A5),MONTH($A5),1),$A$5:$A$800,"<="&$A5)+IF(AND(YEAR($A5)=YEAR(Settings!$B$3),MONTH($A5)=MONTH(Settings!$B$3)),Settings!$B$7,0)) | V5: =IF($A5="","",Settings!$B$8+SUM($B$5:B5)) | W5: =IF($A5="","",Settings!$B$9+SUM($J$5:J5)) | X5: =IF($A5="","",IF(AND(N5>0,F5>0),ROUND(F5/N5,0),Settings!$B$5)) | Y5: =IF($A5="","",IF(AND(M5>0,L5>0),ROUND(L5/M5,0),IF(AND(J5>0,B5>0),ROUND(B5/J5,0),Settings!$B$5)))
I6: =IF($A6="","",R5) | J6: =IF($A6="","",IF(C6="",0,C6)) | K6: =IF($A6="","",IF(E6="",0,E6)) | L6: =IF($A6="","",B6-D6) | M6: =IF($A6="","",J6-K6) | N6: =IF($A6="","",IF(G6="",0,G6)) | O6: =IF($A6="","",D6+F6) | P6: =IF($A6="","",K6+N6) | Q6: =IF($A6="","",I6+L6-F6) | R6: =IF($A6="","",IF(H6="",Q6,H6)) | S6: =IF($A6="","",R6-Q6) | T6: =IF($A6="","",SUMIFS($B$5:$B$800,$A$5:$A$800,">="&DATE(YEAR($A6),MONTH($A6),1),$A$5:$A$800,"<="&$A6)+IF(AND(YEAR($A6)=YEAR(Settings!$B$3),MONTH($A6)=MONTH(Settings!$B$3)),Settings!$B$6,0)) | U6: =IF($A6="","",SUMIFS($J$5:$J$800,$A$5:$A$800,">="&DATE(YEAR($A6),MONTH($A6),1),$A$5:$A$800,"<="&$A6)+IF(AND(YEAR($A6)=YEAR(Settings!$B$3),MONTH($A6)=MONTH(Settings!$B$3)),Settings!$B$7,0)) | V6: =IF($A6="","",Settings!$B$8+SUM($B$5:B6)) | W6: =IF($A6="","",Settings!$B$9+SUM($J$5:J6)) | X6: =IF($A6="","",IF(AND(N6>0,F6>0),ROUND(F6/N6,0),X5)) | Y6: =IF($A6="","",IF(AND(M6>0,L6>0),ROUND(L6/M6,0),IF(AND(J6>0,B6>0),ROUND(B6/J6,0),Y5)))
I7: =IF($A7="","",R6) | J7: =IF($A7="","",IF(C7="",0,C7)) | K7: =IF($A7="","",IF(E7="",0,E7)) | L7: =IF($A7="","",B7-D7) | M7: =IF($A7="","",J7-K7) | N7: =IF($A7="","",IF(G7="",0,G7)) | O7: =IF($A7="","",D7+F7) | P7: =IF($A7="","",K7+N7) | Q7: =IF($A7="","",I7+L7-F7) | R7: =IF($A7="","",IF(H7="",Q7,H7)) | S7: =IF($A7="","",R7-Q7) | T7: =IF($A7="","",SUMIFS($B$5:$B$800,$A$5:$A$800,">="&DATE(YEAR($A7),MONTH($A7),1),$A$5:$A$800,"<="&$A7)+IF(AND(YEAR($A7)=YEAR(Settings!$B$3),MONTH($A7)=MONTH(Settings!$B$3)),Settings!$B$6,0)) | U7: =IF($A7="","",SUMIFS($J$5:$J$800,$A$5:$A$800,">="&DATE(YEAR($A7),MONTH($A7),1),$A$5:$A$800,"<="&$A7)+IF(AND(YEAR($A7)=YEAR(Settings!$B$3),MONTH($A7)=MONTH(Settings!$B$3)),Settings!$B$7,0)) | V7: =IF($A7="","",Settings!$B$8+SUM($B$5:B7)) | W7: =IF($A7="","",Settings!$B$9+SUM($J$5:J7)) | X7: =IF($A7="","",IF(AND(N7>0,F7>0),ROUND(F7/N7,0),X6)) | Y7: =IF($A7="","",IF(AND(M7>0,L7>0),ROUND(L7/M7,0),IF(AND(J7>0,B7>0),ROUND(B7/J7,0),Y6)))
I8: =IF($A8="","",R7) | J8: =IF($A8="","",IF(C8="",0,C8)) | K8: =IF($A8="","",IF(E8="",0,E8)) | L8: =IF($A8="","",B8-D8) | M8: =IF($A8="","",J8-K8) | N8: =IF($A8="","",IF(G8="",0,G8)) | O8: =IF($A8="","",D8+F8) | P8: =IF($A8="","",K8+N8) | Q8: =IF($A8="","",I8+L8-F8) | R8: =IF($A8="","",IF(H8="",Q8,H8)) | S8: =IF($A8="","",R8-Q8) | T8: =IF($A8="","",SUMIFS($B$5:$B$800,$A$5:$A$800,">="&DATE(YEAR($A8),MONTH($A8),1),$A$5:$A$800,"<="&$A8)+IF(AND(YEAR($A8)=YEAR(Settings!$B$3),MONTH($A8)=MONTH(Settings!$B$3)),Settings!$B$6,0)) | U8: =IF($A8="","",SUMIFS($J$5:$J$800,$A$5:$A$800,">="&DATE(YEAR($A8),MONTH($A8),1),$A$5:$A$800,"<="&$A8)+IF(AND(YEAR($A8)=YEAR(Settings!$B$3),MONTH($A8)=MONTH(Settings!$B$3)),Settings!$B$7,0)) | V8: =IF($A8="","",Settings!$B$8+SUM($B$5:B8)) | W8: =IF($A8="","",Settings!$B$9+SUM($J$5:J8)) | X8: =IF($A8="","",IF(AND(N8>0,F8>0),ROUND(F8/N8,0),X7)) | Y8: =IF($A8="","",IF(AND(M8>0,L8>0),ROUND(L8/M8,0),IF(AND(J8>0,B8>0),ROUND(B8/J8,0),Y7)))
I9: =IF($A9="","",R8) | J9: =IF($A9="","",IF(C9="",0,C9)) | K9: =IF($A9="","",IF(E9="",0,E9)) | L9: =IF($A9="","",B9-D9) | M9: =IF($A9="","",J9-K9) | N9: =IF($A9="","",IF(G9="",0,G9)) | O9: =IF($A9="","",D9+F9) | P9: =IF($A9="","",K9+N9) | Q9: =IF($A9="","",I9+L9-F9) | R9: =IF($A9="","",IF(H9="",Q9,H9)) | S9: =IF($A9="","",R9-Q9) | T9: =IF($A9="","",SUMIFS($B$5:$B$800,$A$5:$A$800,">="&DATE(YEAR($A9),MONTH($A9),1),$A$5:$A$800,"<="&$A9)+IF(AND(YEAR($A9)=YEAR(Settings!$B$3),MONTH($A9)=MONTH(Settings!$B$3)),Settings!$B$6,0)) | U9: =IF($A9="","",SUMIFS($J$5:$J$800,$A$5:$A$800,">="&DATE(YEAR($A9),MONTH($A9),1),$A$5:$A$800,"<="&$A9)+IF(AND(YEAR($A9)=YEAR(Settings!$B$3),MONTH($A9)=MONTH(Settings!$B$3)),Settings!$B$7,0)) | V9: =IF($A9="","",Settings!$B$8+SUM($B$5:B9)) | W9: =IF($A9="","",Settings!$B$9+SUM($J$5:J9)) | X9: =IF($A9="","",IF(AND(N9>0,F9>0),ROUND(F9/N9,0),X8)) | Y9: =IF($A9="","",IF(AND(M9>0,L9>0),ROUND(L9/M9,0),IF(AND(J9>0,B9>0),ROUND(B9/J9,0),Y8)))
I10: =IF($A10="","",R9) | J10: =IF($A10="","",IF(C10="",0,C10)) | K10: =IF($A10="","",IF(E10="",0,E10)) | L10: =IF($A10="","",B10-D10) | M10: =IF($A10="","",J10-K10) | N10: =IF($A10="","",IF(G10="",0,G10)) | O10: =IF($A10="","",D10+F10) | P10: =IF($A10="","",K10+N10) | Q10: =IF($A10="","",I10+L10-F10) | R10: =IF($A10="","",IF(H10="",Q10,H10)) | S10: =IF($A10="","",R10-Q10) | T10: =IF($A10="","",SUMIFS($B$5:$B$800,$A$5:$A$800,">="&DATE(YEAR($A10),MONTH($A10),1),$A$5:$A$800,"<="&$A10)+IF(AND(YEAR($A10)=YEAR(Settings!$B$3),MONTH($A10)=MONTH(Settings!$B$3)),Settings!$B$6,0)) | U10: =IF($A10="","",SUMIFS($J$5:$J$800,$A$5:$A$800,">="&DATE(YEAR($A10),MONTH($A10),1),$A$5:$A$800,"<="&$A10)+IF(AND(YEAR($A10)=YEAR(Settings!$B$3),MONTH($A10)=MONTH(Settings!$B$3)),Settings!$B$7,0)) | V10: =IF($A10="","",Settings!$B$8+SUM($B$5:B10)) | W10: =IF($A10="","",Settings!$B$9+SUM($J$5:J10)) | X10: =IF($A10="","",IF(AND(N10>0,F10>0),ROUND(F10/N10,0),X9)) | Y10: =IF($A10="","",IF(AND(M10>0,L10>0),ROUND(L10/M10,0),IF(AND(J10>0,B10>0),ROUND(B10/J10,0),Y9)))
I11: =IF($A11="","",R10) | J11: =IF($A11="","",IF(C11="",0,C11)) | K11: =IF($A11="","",IF(E11="",0,E11)) | L11: =IF($A11="","",B11-D11) | M11: =IF($A11="","",J11-K11) | N11: =IF($A11="","",IF(G11="",0,G11)) | O11: =IF($A11="","",D11+F11) | P11: =IF($A11="","",K11+N11) | Q11: =IF($A11="","",I11+L11-F11) | R11: =IF($A11="","",IF(H11="",Q11,H11)) | S11: =IF($A11="","",R11-Q11) | T11: =IF($A11="","",SUMIFS($B$5:$B$800,$A$5:$A$800,">="&DATE(YEAR($A11),MONTH($A11),1),$A$5:$A$800,"<="&$A11)+IF(AND(YEAR($A11)=YEAR(Settings!$B$3),MONTH($A11)=MONTH(Settings!$B$3)),Settings!$B$6,0)) | U11: =IF($A11="","",SUMIFS($J$5:$J$800,$A$5:$A$800,">="&DATE(YEAR($A11),MONTH($A11),1),$A$5:$A$800,"<="&$A11)+IF(AND(YEAR($A11)=YEAR(Settings!$B$3),MONTH($A11)=MONTH(Settings!$B$3)),Settings!$B$7,0)) | V11: =IF($A11="","",Settings!$B$8+SUM($B$5:B11)) | W11: =IF($A11="","",Settings!$B$9+SUM($J$5:J11)) | X11: =IF($A11="","",IF(AND(N11>0,F11>0),ROUND(F11/N11,0),X10)) | Y11: =IF($A11="","",IF(AND(M11>0,L11>0),ROUND(L11/M11,0),IF(AND(J11>0,B11>0),ROUND(B11/J11,0),Y10)))
I12: =IF($A12="","",R11) | J12: =IF($A12="","",IF(C12="",0,C12)) | K12: =IF($A12="","",IF(E12="",0,E12)) | L12: =IF($A12="","",B12-D12) | M12: =IF($A12="","",J12-K12) | N12: =IF($A12="","",IF(G12="",0,G12)) | O12: =IF($A12="","",D12+F12) | P12: =IF($A12="","",K12+N12) | Q12: =IF($A12="","",I12+L12-F12) | R12: =IF($A12="","",IF(H12="",Q12,H12)) | S12: =IF($A12="","",R12-Q12) | T12: =IF($A12="","",SUMIFS($B$5:$B$800,$A$5:$A$800,">="&DATE(YEAR($A12),MONTH($A12),1),$A$5:$A$800,"<="&$A12)+IF(AND(YEAR($A12)=YEAR(Settings!$B$3),MONTH($A12)=MONTH(Settings!$B$3)),Settings!$B$6,0)) | U12: =IF($A12="","",SUMIFS($J$5:$J$800,$A$5:$A$800,">="&DATE(YEAR($A12),MONTH($A12),1),$A$5:$A$800,"<="&$A12)+IF(AND(YEAR($A12)=YEAR(Settings!$B$3),MONTH($A12)=MONTH(Settings!$B$3)),Settings!$B$7,0)) | V12: =IF($A12="","",Settings!$B$8+SUM($B$5:B12)) | W12: =IF($A12="","",Settings!$B$9+SUM($J$5:J12)) | X12: =IF($A12="","",IF(AND(N12>0,F12>0),ROUND(F12/N12,0),X11)) | Y12: =IF($A12="","",IF(AND(M12>0,L12>0),ROUND(L12/M12,0),IF(AND(J12>0,B12>0),ROUND(B12/J12,0),Y11)))
I13: =IF($A13="","",R12) | J13: =IF($A13="","",IF(C13="",0,C13)) | K13: =IF($A13="","",IF(E13="",0,E13)) | L13: =IF($A13="","",B13-D13) | M13: =IF($A13="","",J13-K13) | N13: =IF($A13="","",IF(G13="",0,G13)) | O13: =IF($A13="","",D13+F13) | P13: =IF($A13="","",K13+N13) | Q13: =IF($A13="","",I13+L13-F13) | R13: =IF($A13="","",IF(H13="",Q13,H13)) | S13: =IF($A13="","",R13-Q13) | T13: =IF($A13="","",SUMIFS($B$5:$B$800,$A$5:$A$800,">="&DATE(YEAR($A13),MONTH($A13),1),$A$5:$A$800,"<="&$A13)+IF(AND(YEAR($A13)=YEAR(Settings!$B$3),MONTH($A13)=MONTH(Settings!$B$3)),Settings!$B$6,0)) | U13: =IF($A13="","",SUMIFS($J$5:$J$800,$A$5:$A$800,">="&DATE(YEAR($A13),MONTH($A13),1),$A$5:$A$800,"<="&$A13)+IF(AND(YEAR($A13)=YEAR(Settings!$B$3),MONTH($A13)=MONTH(Settings!$B$3)),Settings!$B$7,0)) | V13: =IF($A13="","",Settings!$B$8+SUM($B$5:B13)) | W13: =IF($A13="","",Settings!$B$9+SUM($J$5:J13)) | X13: =IF($A13="","",IF(AND(N13>0,F13>0),ROUND(F13/N13,0),X12)) | Y13: =IF($A13="","",IF(AND(M13>0,L13>0),ROUND(L13/M13,0),IF(AND(J13>0,B13>0),ROUND(B13/J13,0),Y12)))
I14: =IF($A14="","",R13) | J14: =IF($A14="","",IF(C14="",0,C14)) | K14: =IF($A14="","",IF(E14="",0,E14)) | L14: =IF($A14="","",B14-D14) | M14: =IF($A14="","",J14-K14) | N14: =IF($A14="","",IF(G14="",0,G14)) | O14: =IF($A14="","",D14+F14) | P14: =IF($A14="","",K14+N14) | Q14: =IF($A14="","",I14+L14-F14) | R14: =IF($A14="","",IF(H14="",Q14,H14)) | S14: =IF($A14="","",R14-Q14) | T14: =IF($A14="","",SUMIFS($B$5:$B$800,$A$5:$A$800,">="&DATE(YEAR($A14),MONTH($A14),1),$A$5:$A$800,"<="&$A14)+IF(AND(YEAR($A14)=YEAR(Settings!$B$3),MONTH($A14)=MONTH(Settings!$B$3)),Settings!$B$6,0)) | U14: =IF($A14="","",SUMIFS($J$5:$J$800,$A$5:$A$800,">="&DATE(YEAR($A14),MONTH($A14),1),$A$5:$A$800,"<="&$A14)+IF(AND(YEAR($A14)=YEAR(Settings!$B$3),MONTH($A14)=MONTH(Settings!$B$3)),Settings!$B$7,0)) | V14: =IF($A14="","",Settings!$B$8+SUM($B$5:B14)) | W14: =IF($A14="","",Settings!$B$9+SUM($J$5:J14)) | X14: =IF($A14="","",IF(AND(N14>0,F14>0),ROUND(F14/N14,0),X13)) | Y14: =IF($A14="","",IF(AND(M14>0,L14>0),ROUND(L14/M14,0),IF(AND(J14>0,B14>0),ROUND(B14/J14,0),Y13)))
I15: =IF($A15="","",R14) | J15: =IF($A15="","",IF(C15="",0,C15)) | K15: =IF($A15="","",IF(E15="",0,E15)) | L15: =IF($A15="","",B15-D15) | M15: =IF($A15="","",J15-K15) | N15: =IF($A15="","",IF(G15="",0,G15)) | O15: =IF($A15="","",D15+F15) | P15: =IF($A15="","",K15+N15) | Q15: =IF($A15="","",I15+L15-F15) | R15: =IF($A15="","",IF(H15="",Q15,H15)) | S15: =IF($A15="","",R15-Q15) | T15: =IF($A15="","",SUMIFS($B$5:$B$800,$A$5:$A$800,">="&DATE(YEAR($A15),MONTH($A15),1),$A$5:$A$800,"<="&$A15)+IF(AND(YEAR($A15)=YEAR(Settings!$B$3),MONTH($A15)=MONTH(Settings!$B$3)),Settings!$B$6,0)) | U15: =IF($A15="","",SUMIFS($J$5:$J$800,$A$5:$A$800,">="&DATE(YEAR($A15),MONTH($A15),1),$A$5:$A$800,"<="&$A15)+IF(AND(YEAR($A15)=YEAR(Settings!$B$3),MONTH($A15)=MONTH(Settings!$B$3)),Settings!$B$7,0)) | V15: =IF($A15="","",Settings!$B$8+SUM($B$5:B15)) | W15: =IF($A15="","",Settings!$B$9+SUM($J$5:J15)) | X15: =IF($A15="","",IF(AND(N15>0,F15>0),ROUND(F15/N15,0),X14)) | Y15: =IF($A15="","",IF(AND(M15>0,L15>0),ROUND(L15/M15,0),IF(AND(J15>0,B15>0),ROUND(B15/J15,0),Y14)))
I16: =IF($A16="","",R15) | J16: =IF($A16="","",IF(C16="",0,C16)) | K16: =IF($A16="","",IF(E16="",0,E16)) | L16: =IF($A16="","",B16-D16) | M16: =IF($A16="","",J16-K16) | N16: =IF($A16="","",IF(G16="",0,G16)) | O16: =IF($A16="","",D16+F16) | P16: =IF($A16="","",K16+N16) | Q16: =IF($A16="","",I16+L16-F16) | R16: =IF($A16="","",IF(H16="",Q16,H16)) | S16: =IF($A16="","",R16-Q16) | T16: =IF($A16="","",SUMIFS($B$5:$B$800,$A$5:$A$800,">="&DATE(YEAR($A16),MONTH($A16),1),$A$5:$A$800,"<="&$A16)+IF(AND(YEAR($A16)=YEAR(Settings!$B$3),MONTH($A16)=MONTH(Settings!$B$3)),Settings!$B$6,0)) | U16: =IF($A16="","",SUMIFS($J$5:$J$800,$A$5:$A$800,">="&DATE(YEAR($A16),MONTH($A16),1),$A$5:$A$800,"<="&$A16)+IF(AND(YEAR($A16)=YEAR(Settings!$B$3),MONTH($A16)=MONTH(Settings!$B$3)),Settings!$B$7,0)) | V16: =IF($A16="","",Settings!$B$8+SUM($B$5:B16)) | W16: =IF($A16="","",Settings!$B$9+SUM($J$5:J16)) | X16: =IF($A16="","",IF(AND(N16>0,F16>0),ROUND(F16/N16,0),X15)) | Y16: =IF($A16="","",IF(AND(M16>0,L16>0),ROUND(L16/M16,0),IF(AND(J16>0,B16>0),ROUND(B16/J16,0),Y15)))
I17: =IF($A17="","",R16) | J17: =IF($A17="","",IF(C17="",0,C17)) | K17: =IF($A17="","",IF(E17="",0,E17)) | L17: =IF($A17="","",B17-D17) | M17: =IF($A17="","",J17-K17) | N17: =IF($A17="","",IF(G17="",0,G17)) | O17: =IF($A17="","",D17+F17) | P17: =IF($A17="","",K17+N17) | Q17: =IF($A17="","",I17+L17-F17) | R17: =IF($A17="","",IF(H17="",Q17,H17)) | S17: =IF($A17="","",R17-Q17) | T17: =IF($A17="","",SUMIFS($B$5:$B$800,$A$5:$A$800,">="&DATE(YEAR($A17),MONTH($A17),1),$A$5:$A$800,"<="&$A17)+IF(AND(YEAR($A17)=YEAR(Settings!$B$3),MONTH($A17)=MONTH(Settings!$B$3)),Settings!$B$6,0)) | U17: =IF($A17="","",SUMIFS($J$5:$J$800,$A$5:$A$800,">="&DATE(YEAR($A17),MONTH($A17),1),$A$5:$A$800,"<="&$A17)+IF(AND(YEAR($A17)=YEAR(Settings!$B$3),MONTH($A17)=MONTH(Settings!$B$3)),Settings!$B$7,0)) | V17: =IF($A17="","",Settings!$B$8+SUM($B$5:B17)) | W17: =IF($A17="","",Settings!$B$9+SUM($J$5:J17)) | X17: =IF($A17="","",IF(AND(N17>0,F17>0),ROUND(F17/N17,0),X16)) | Y17: =IF($A17="","",IF(AND(M17>0,L17>0),ROUND(L17/M17,0),IF(AND(J17>0,B17>0),ROUND(B17/J17,0),Y16)))
... I800: =IF($A800="","",R799) | J800: =IF($A800="","",IF(C800="",0,C800)) | K800: =IF($A800="","",IF(E800="",0,E800)) | L800: =IF($A800="","",B800-D800) | M800: =IF($A800="","",J800-K800) | N800: =IF($A800="","",IF(G800="",0,G800)) | O800: =IF($A800="","",D800+F800) | P800: =IF($A800="","",K800+N800) | Q800: =IF($A800="","",I800+L800-F800) | R800: =IF($A800="","",IF(H800="",Q800,H800)) | S800: =IF($A800="","",R800-Q800) | T800: =IF($A800="","",SUMIFS($B$5:$B$800,$A$5:$A$800,">="&DATE(YEAR($A800),MONTH($A800),1),$A$5:$A$800,"<="&$A800)+IF(AND(YEAR($A800)=YEAR(Settings!$B$3),MONTH($A800)=MONTH(Settings!$B$3)),Settings!$B$6,0)) | U800: =IF($A800="","",SUMIFS($J$5:$J$800,$A$5:$A$800,">="&DATE(YEAR($A800),MONTH($A800),1),$A$5:$A$800,"<="&$A800)+IF(AND(YEAR($A800)=YEAR(Settings!$B$3),MONTH($A800)=MONTH(Settings!$B$3)),Settings!$B$7,0)) | V800: =IF($A800="","",Settings!$B$8+SUM($B$5:B800)) | W800: =IF($A800="","",Settings!$B$9+SUM($J$5:J800)) | X800: =IF($A800="","",IF(AND(N800>0,F800>0),ROUND(F800/N800,0),X799)) | Y800: =IF($A800="","",IF(AND(M800>0,L800>0),ROUND(L800/M800,0),IF(AND(J800>0,B800>0),ROUND(B800/J800,0),Y799)))

Sheet Daily Dispatch
A1: BLOCK 2 – TODAY'S DISPATCH + BLOCK 3 – MONTHLY DISPATCH STATUS (one row per day)
A2: Type only the yellow columns: Date, and MT + Trips for each material. Blank or 0 = NIL.
B3: TODAY'S DISPATCH – YOU TYPE | J3: TODAY'S TOTALS | N3: MONTHLY DISPATCH STATUS (month to date)
A4: Date | B4: 10 MM Aggregate MT | C4: 10 MM Trips | D4: 20 MM Aggregate MT | E4: 20 MM Trips | F4: 30 MM Aggregate MT | G4: 30 MM Trips | H4: M-Sand MT | I4: M-Sand Trips | J4: Total Aggregate Dispatch MT | K4: Total Aggregate Trips | L4: Total Dispatch All Material MT | M4: Total Dispatch Trips | N4: Aggregate This Month MT | O4: Aggregate This Month Trips | P4: M-Sand This Month MT | Q4: M-Sand This Month Trips | R4: All Material This Month MT | S4: All Material This Month Trips
J5: =IF($A5="","",B5+D5+F5) | K5: =IF($A5="","",C5+E5+G5) | L5: =IF($A5="","",J5+H5) | M5: =IF($A5="","",K5+I5) | N5: =IF($A5="","",SUMIFS($J$5:$J$800,$A$5:$A$800,">="&DATE(YEAR($A5),MONTH($A5),1),$A$5:$A$800,"<="&$A5)+IF(AND(YEAR($A5)=YEAR(Settings!$B$3),MONTH($A5)=MONTH(Settings!$B$3)),Settings!$B$10,0)) | O5: =IF($A5="","",SUMIFS($K$5:$K$800,$A$5:$A$800,">="&DATE(YEAR($A5),MONTH($A5),1),$A$5:$A$800,"<="&$A5)+IF(AND(YEAR($A5)=YEAR(Settings!$B$3),MONTH($A5)=MONTH(Settings!$B$3)),Settings!$B$11,0)) | P5: =IF($A5="","",SUMIFS($H$5:$H$800,$A$5:$A$800,">="&DATE(YEAR($A5),MONTH($A5),1),$A$5:$A$800,"<="&$A5)+IF(AND(YEAR($A5)=YEAR(Settings!$B$3),MONTH($A5)=MONTH(Settings!$B$3)),Settings!$B$12,0)) | Q5: =IF($A5="","",SUMIFS($I$5:$I$800,$A$5:$A$800,">="&DATE(YEAR($A5),MONTH($A5),1),$A$5:$A$800,"<="&$A5)+IF(AND(YEAR($A5)=YEAR(Settings!$B$3),MONTH($A5)=MONTH(Settings!$B$3)),Settings!$B$13,0)) | R5: =IF($A5="","",N5+P5) | S5: =IF($A5="","",O5+Q5)
J6: =IF($A6="","",B6+D6+F6) | K6: =IF($A6="","",C6+E6+G6) | L6: =IF($A6="","",J6+H6) | M6: =IF($A6="","",K6+I6) | N6: =IF($A6="","",SUMIFS($J$5:$J$800,$A$5:$A$800,">="&DATE(YEAR($A6),MONTH($A6),1),$A$5:$A$800,"<="&$A6)+IF(AND(YEAR($A6)=YEAR(Settings!$B$3),MONTH($A6)=MONTH(Settings!$B$3)),Settings!$B$10,0)) | O6: =IF($A6="","",SUMIFS($K$5:$K$800,$A$5:$A$800,">="&DATE(YEAR($A6),MONTH($A6),1),$A$5:$A$800,"<="&$A6)+IF(AND(YEAR($A6)=YEAR(Settings!$B$3),MONTH($A6)=MONTH(Settings!$B$3)),Settings!$B$11,0)) | P6: =IF($A6="","",SUMIFS($H$5:$H$800,$A$5:$A$800,">="&DATE(YEAR($A6),MONTH($A6),1),$A$5:$A$800,"<="&$A6)+IF(AND(YEAR($A6)=YEAR(Settings!$B$3),MONTH($A6)=MONTH(Settings!$B$3)),Settings!$B$12,0)) | Q6: =IF($A6="","",SUMIFS($I$5:$I$800,$A$5:$A$800,">="&DATE(YEAR($A6),MONTH($A6),1),$A$5:$A$800,"<="&$A6)+IF(AND(YEAR($A6)=YEAR(Settings!$B$3),MONTH($A6)=MONTH(Settings!$B$3)),Settings!$B$13,0)) | R6: =IF($A6="","",N6+P6) | S6: =IF($A6="","",O6+Q6)
J7: =IF($A7="","",B7+D7+F7) | K7: =IF($A7="","",C7+E7+G7) | L7: =IF($A7="","",J7+H7) | M7: =IF($A7="","",K7+I7) | N7: =IF($A7="","",SUMIFS($J$5:$J$800,$A$5:$A$800,">="&DATE(YEAR($A7),MONTH($A7),1),$A$5:$A$800,"<="&$A7)+IF(AND(YEAR($A7)=YEAR(Settings!$B$3),MONTH($A7)=MONTH(Settings!$B$3)),Settings!$B$10,0)) | O7: =IF($A7="","",SUMIFS($K$5:$K$800,$A$5:$A$800,">="&DATE(YEAR($A7),MONTH($A7),1),$A$5:$A$800,"<="&$A7)+IF(AND(YEAR($A7)=YEAR(Settings!$B$3),MONTH($A7)=MONTH(Settings!$B$3)),Settings!$B$11,0)) | P7: =IF($A7="","",SUMIFS($H$5:$H$800,$A$5:$A$800,">="&DATE(YEAR($A7),MONTH($A7),1),$A$5:$A$800,"<="&$A7)+IF(AND(YEAR($A7)=YEAR(Settings!$B$3),MONTH($A7)=MONTH(Settings!$B$3)),Settings!$B$12,0)) | Q7: =IF($A7="","",SUMIFS($I$5:$I$800,$A$5:$A$800,">="&DATE(YEAR($A7),MONTH($A7),1),$A$5:$A$800,"<="&$A7)+IF(AND(YEAR($A7)=YEAR(Settings!$B$3),MONTH($A7)=MONTH(Settings!$B$3)),Settings!$B$13,0)) | R7: =IF($A7="","",N7+P7) | S7: =IF($A7="","",O7+Q7)
J8: =IF($A8="","",B8+D8+F8) | K8: =IF($A8="","",C8+E8+G8) | L8: =IF($A8="","",J8+H8) | M8: =IF($A8="","",K8+I8) | N8: =IF($A8="","",SUMIFS($J$5:$J$800,$A$5:$A$800,">="&DATE(YEAR($A8),MONTH($A8),1),$A$5:$A$800,"<="&$A8)+IF(AND(YEAR($A8)=YEAR(Settings!$B$3),MONTH($A8)=MONTH(Settings!$B$3)),Settings!$B$10,0)) | O8: =IF($A8="","",SUMIFS($K$5:$K$800,$A$5:$A$800,">="&DATE(YEAR($A8),MONTH($A8),1),$A$5:$A$800,"<="&$A8)+IF(AND(YEAR($A8)=YEAR(Settings!$B$3),MONTH($A8)=MONTH(Settings!$B$3)),Settings!$B$11,0)) | P8: =IF($A8="","",SUMIFS($H$5:$H$800,$A$5:$A$800,">="&DATE(YEAR($A8),MONTH($A8),1),$A$5:$A$800,"<="&$A8)+IF(AND(YEAR($A8)=YEAR(Settings!$B$3),MONTH($A8)=MONTH(Settings!$B$3)),Settings!$B$12,0)) | Q8: =IF($A8="","",SUMIFS($I$5:$I$800,$A$5:$A$800,">="&DATE(YEAR($A8),MONTH($A8),1),$A$5:$A$800,"<="&$A8)+IF(AND(YEAR($A8)=YEAR(Settings!$B$3),MONTH($A8)=MONTH(Settings!$B$3)),Settings!$B$13,0)) | R8: =IF($A8="","",N8+P8) | S8: =IF($A8="","",O8+Q8)
J9: =IF($A9="","",B9+D9+F9) | K9: =IF($A9="","",C9+E9+G9) | L9: =IF($A9="","",J9+H9) | M9: =IF($A9="","",K9+I9) | N9: =IF($A9="","",SUMIFS($J$5:$J$800,$A$5:$A$800,">="&DATE(YEAR($A9),MONTH($A9),1),$A$5:$A$800,"<="&$A9)+IF(AND(YEAR($A9)=YEAR(Settings!$B$3),MONTH($A9)=MONTH(Settings!$B$3)),Settings!$B$10,0)) | O9: =IF($A9="","",SUMIFS($K$5:$K$800,$A$5:$A$800,">="&DATE(YEAR($A9),MONTH($A9),1),$A$5:$A$800,"<="&$A9)+IF(AND(YEAR($A9)=YEAR(Settings!$B$3),MONTH($A9)=MONTH(Settings!$B$3)),Settings!$B$11,0)) | P9: =IF($A9="","",SUMIFS($H$5:$H$800,$A$5:$A$800,">="&DATE(YEAR($A9),MONTH($A9),1),$A$5:$A$800,"<="&$A9)+IF(AND(YEAR($A9)=YEAR(Settings!$B$3),MONTH($A9)=MONTH(Settings!$B$3)),Settings!$B$12,0)) | Q9: =IF($A9="","",SUMIFS($I$5:$I$800,$A$5:$A$800,">="&DATE(YEAR($A9),MONTH($A9),1),$A$5:$A$800,"<="&$A9)+IF(AND(YEAR($A9)=YEAR(Settings!$B$3),MONTH($A9)=MONTH(Settings!$B$3)),Settings!$B$13,0)) | R9: =IF($A9="","",N9+P9) | S9: =IF($A9="","",O9+Q9)
J10: =IF($A10="","",B10+D10+F10) | K10: =IF($A10="","",C10+E10+G10) | L10: =IF($A10="","",J10+H10) | M10: =IF($A10="","",K10+I10) | N10: =IF($A10="","",SUMIFS($J$5:$J$800,$A$5:$A$800,">="&DATE(YEAR($A10),MONTH($A10),1),$A$5:$A$800,"<="&$A10)+IF(AND(YEAR($A10)=YEAR(Settings!$B$3),MONTH($A10)=MONTH(Settings!$B$3)),Settings!$B$10,0)) | O10: =IF($A10="","",SUMIFS($K$5:$K$800,$A$5:$A$800,">="&DATE(YEAR($A10),MONTH($A10),1),$A$5:$A$800,"<="&$A10)+IF(AND(YEAR($A10)=YEAR(Settings!$B$3),MONTH($A10)=MONTH(Settings!$B$3)),Settings!$B$11,0)) | P10: =IF($A10="","",SUMIFS($H$5:$H$800,$A$5:$A$800,">="&DATE(YEAR($A10),MONTH($A10),1),$A$5:$A$800,"<="&$A10)+IF(AND(YEAR($A10)=YEAR(Settings!$B$3),MONTH($A10)=MONTH(Settings!$B$3)),Settings!$B$12,0)) | Q10: =IF($A10="","",SUMIFS($I$5:$I$800,$A$5:$A$800,">="&DATE(YEAR($A10),MONTH($A10),1),$A$5:$A$800,"<="&$A10)+IF(AND(YEAR($A10)=YEAR(Settings!$B$3),MONTH($A10)=MONTH(Settings!$B$3)),Settings!$B$13,0)) | R10: =IF($A10="","",N10+P10) | S10: =IF($A10="","",O10+Q10)
J11: =IF($A11="","",B11+D11+F11) | K11: =IF($A11="","",C11+E11+G11) | L11: =IF($A11="","",J11+H11) | M11: =IF($A11="","",K11+I11) | N11: =IF($A11="","",SUMIFS($J$5:$J$800,$A$5:$A$800,">="&DATE(YEAR($A11),MONTH($A11),1),$A$5:$A$800,"<="&$A11)+IF(AND(YEAR($A11)=YEAR(Settings!$B$3),MONTH($A11)=MONTH(Settings!$B$3)),Settings!$B$10,0)) | O11: =IF($A11="","",SUMIFS($K$5:$K$800,$A$5:$A$800,">="&DATE(YEAR($A11),MONTH($A11),1),$A$5:$A$800,"<="&$A11)+IF(AND(YEAR($A11)=YEAR(Settings!$B$3),MONTH($A11)=MONTH(Settings!$B$3)),Settings!$B$11,0)) | P11: =IF($A11="","",SUMIFS($H$5:$H$800,$A$5:$A$800,">="&DATE(YEAR($A11),MONTH($A11),1),$A$5:$A$800,"<="&$A11)+IF(AND(YEAR($A11)=YEAR(Settings!$B$3),MONTH($A11)=MONTH(Settings!$B$3)),Settings!$B$12,0)) | Q11: =IF($A11="","",SUMIFS($I$5:$I$800,$A$5:$A$800,">="&DATE(YEAR($A11),MONTH($A11),1),$A$5:$A$800,"<="&$A11)+IF(AND(YEAR($A11)=YEAR(Settings!$B$3),MONTH($A11)=MONTH(Settings!$B$3)),Settings!$B$13,0)) | R11: =IF($A11="","",N11+P11) | S11: =IF($A11="","",O11+Q11)
J12: =IF($A12="","",B12+D12+F12) | K12: =IF($A12="","",C12+E12+G12) | L12: =IF($A12="","",J12+H12) | M12: =IF($A12="","",K12+I12) | N12: =IF($A12="","",SUMIFS($J$5:$J$800,$A$5:$A$800,">="&DATE(YEAR($A12),MONTH($A12),1),$A$5:$A$800,"<="&$A12)+IF(AND(YEAR($A12)=YEAR(Settings!$B$3),MONTH($A12)=MONTH(Settings!$B$3)),Settings!$B$10,0)) | O12: =IF($A12="","",SUMIFS($K$5:$K$800,$A$5:$A$800,">="&DATE(YEAR($A12),MONTH($A12),1),$A$5:$A$800,"<="&$A12)+IF(AND(YEAR($A12)=YEAR(Settings!$B$3),MONTH($A12)=MONTH(Settings!$B$3)),Settings!$B$11,0)) | P12: =IF($A12="","",SUMIFS($H$5:$H$800,$A$5:$A$800,">="&DATE(YEAR($A12),MONTH($A12),1),$A$5:$A$800,"<="&$A12)+IF(AND(YEAR($A12)=YEAR(Settings!$B$3),MONTH($A12)=MONTH(Settings!$B$3)),Settings!$B$12,0)) | Q12: =IF($A12="","",SUMIFS($I$5:$I$800,$A$5:$A$800,">="&DATE(YEAR($A12),MONTH($A12),1),$A$5:$A$800,"<="&$A12)+IF(AND(YEAR($A12)=YEAR(Settings!$B$3),MONTH($A12)=MONTH(Settings!$B$3)),Settings!$B$13,0)) | R12: =IF($A12="","",N12+P12) | S12: =IF($A12="","",O12+Q12)
J13: =IF($A13="","",B13+D13+F13) | K13: =IF($A13="","",C13+E13+G13) | L13: =IF($A13="","",J13+H13) | M13: =IF($A13="","",K13+I13) | N13: =IF($A13="","",SUMIFS($J$5:$J$800,$A$5:$A$800,">="&DATE(YEAR($A13),MONTH($A13),1),$A$5:$A$800,"<="&$A13)+IF(AND(YEAR($A13)=YEAR(Settings!$B$3),MONTH($A13)=MONTH(Settings!$B$3)),Settings!$B$10,0)) | O13: =IF($A13="","",SUMIFS($K$5:$K$800,$A$5:$A$800,">="&DATE(YEAR($A13),MONTH($A13),1),$A$5:$A$800,"<="&$A13)+IF(AND(YEAR($A13)=YEAR(Settings!$B$3),MONTH($A13)=MONTH(Settings!$B$3)),Settings!$B$11,0)) | P13: =IF($A13="","",SUMIFS($H$5:$H$800,$A$5:$A$800,">="&DATE(YEAR($A13),MONTH($A13),1),$A$5:$A$800,"<="&$A13)+IF(AND(YEAR($A13)=YEAR(Settings!$B$3),MONTH($A13)=MONTH(Settings!$B$3)),Settings!$B$12,0)) | Q13: =IF($A13="","",SUMIFS($I$5:$I$800,$A$5:$A$800,">="&DATE(YEAR($A13),MONTH($A13),1),$A$5:$A$800,"<="&$A13)+IF(AND(YEAR($A13)=YEAR(Settings!$B$3),MONTH($A13)=MONTH(Settings!$B$3)),Settings!$B$13,0)) | R13: =IF($A13="","",N13+P13) | S13: =IF($A13="","",O13+Q13)
J14: =IF($A14="","",B14+D14+F14) | K14: =IF($A14="","",C14+E14+G14) | L14: =IF($A14="","",J14+H14) | M14: =IF($A14="","",K14+I14) | N14: =IF($A14="","",SUMIFS($J$5:$J$800,$A$5:$A$800,">="&DATE(YEAR($A14),MONTH($A14),1),$A$5:$A$800,"<="&$A14)+IF(AND(YEAR($A14)=YEAR(Settings!$B$3),MONTH($A14)=MONTH(Settings!$B$3)),Settings!$B$10,0)) | O14: =IF($A14="","",SUMIFS($K$5:$K$800,$A$5:$A$800,">="&DATE(YEAR($A14),MONTH($A14),1),$A$5:$A$800,"<="&$A14)+IF(AND(YEAR($A14)=YEAR(Settings!$B$3),MONTH($A14)=MONTH(Settings!$B$3)),Settings!$B$11,0)) | P14: =IF($A14="","",SUMIFS($H$5:$H$800,$A$5:$A$800,">="&DATE(YEAR($A14),MONTH($A14),1),$A$5:$A$800,"<="&$A14)+IF(AND(YEAR($A14)=YEAR(Settings!$B$3),MONTH($A14)=MONTH(Settings!$B$3)),Settings!$B$12,0)) | Q14: =IF($A14="","",SUMIFS($I$5:$I$800,$A$5:$A$800,">="&DATE(YEAR($A14),MONTH($A14),1),$A$5:$A$800,"<="&$A14)+IF(AND(YEAR($A14)=YEAR(Settings!$B$3),MONTH($A14)=MONTH(Settings!$B$3)),Settings!$B$13,0)) | R14: =IF($A14="","",N14+P14) | S14: =IF($A14="","",O14+Q14)
J15: =IF($A15="","",B15+D15+F15) | K15: =IF($A15="","",C15+E15+G15) | L15: =IF($A15="","",J15+H15) | M15: =IF($A15="","",K15+I15) | N15: =IF($A15="","",SUMIFS($J$5:$J$800,$A$5:$A$800,">="&DATE(YEAR($A15),MONTH($A15),1),$A$5:$A$800,"<="&$A15)+IF(AND(YEAR($A15)=YEAR(Settings!$B$3),MONTH($A15)=MONTH(Settings!$B$3)),Settings!$B$10,0)) | O15: =IF($A15="","",SUMIFS($K$5:$K$800,$A$5:$A$800,">="&DATE(YEAR($A15),MONTH($A15),1),$A$5:$A$800,"<="&$A15)+IF(AND(YEAR($A15)=YEAR(Settings!$B$3),MONTH($A15)=MONTH(Settings!$B$3)),Settings!$B$11,0)) | P15: =IF($A15="","",SUMIFS($H$5:$H$800,$A$5:$A$800,">="&DATE(YEAR($A15),MONTH($A15),1),$A$5:$A$800,"<="&$A15)+IF(AND(YEAR($A15)=YEAR(Settings!$B$3),MONTH($A15)=MONTH(Settings!$B$3)),Settings!$B$12,0)) | Q15: =IF($A15="","",SUMIFS($I$5:$I$800,$A$5:$A$800,">="&DATE(YEAR($A15),MONTH($A15),1),$A$5:$A$800,"<="&$A15)+IF(AND(YEAR($A15)=YEAR(Settings!$B$3),MONTH($A15)=MONTH(Settings!$B$3)),Settings!$B$13,0)) | R15: =IF($A15="","",N15+P15) | S15: =IF($A15="","",O15+Q15)
J16: =IF($A16="","",B16+D16+F16) | K16: =IF($A16="","",C16+E16+G16) | L16: =IF($A16="","",J16+H16) | M16: =IF($A16="","",K16+I16) | N16: =IF($A16="","",SUMIFS($J$5:$J$800,$A$5:$A$800,">="&DATE(YEAR($A16),MONTH($A16),1),$A$5:$A$800,"<="&$A16)+IF(AND(YEAR($A16)=YEAR(Settings!$B$3),MONTH($A16)=MONTH(Settings!$B$3)),Settings!$B$10,0)) | O16: =IF($A16="","",SUMIFS($K$5:$K$800,$A$5:$A$800,">="&DATE(YEAR($A16),MONTH($A16),1),$A$5:$A$800,"<="&$A16)+IF(AND(YEAR($A16)=YEAR(Settings!$B$3),MONTH($A16)=MONTH(Settings!$B$3)),Settings!$B$11,0)) | P16: =IF($A16="","",SUMIFS($H$5:$H$800,$A$5:$A$800,">="&DATE(YEAR($A16),MONTH($A16),1),$A$5:$A$800,"<="&$A16)+IF(AND(YEAR($A16)=YEAR(Settings!$B$3),MONTH($A16)=MONTH(Settings!$B$3)),Settings!$B$12,0)) | Q16: =IF($A16="","",SUMIFS($I$5:$I$800,$A$5:$A$800,">="&DATE(YEAR($A16),MONTH($A16),1),$A$5:$A$800,"<="&$A16)+IF(AND(YEAR($A16)=YEAR(Settings!$B$3),MONTH($A16)=MONTH(Settings!$B$3)),Settings!$B$13,0)) | R16: =IF($A16="","",N16+P16) | S16: =IF($A16="","",O16+Q16)
... J800: =IF($A800="","",B800+D800+F800) | K800: =IF($A800="","",C800+E800+G800) | L800: =IF($A800="","",J800+H800) | M800: =IF($A800="","",K800+I800) | N800: =IF($A800="","",SUMIFS($J$5:$J$800,$A$5:$A$800,">="&DATE(YEAR($A800),MONTH($A800),1),$A$5:$A$800,"<="&$A800)+IF(AND(YEAR($A800)=YEAR(Settings!$B$3),MONTH($A800)=MONTH(Settings!$B$3)),Settings!$B$10,0)) | O800: =IF($A800="","",SUMIFS($K$5:$K$800,$A$5:$A$800,">="&DATE(YEAR($A800),MONTH($A800),1),$A$5:$A$800,"<="&$A800)+IF(AND(YEAR($A800)=YEAR(Settings!$B$3),MONTH($A800)=MONTH(Settings!$B$3)),Settings!$B$11,0)) | P800: =IF($A800="","",SUMIFS($H$5:$H$800,$A$5:$A$800,">="&DATE(YEAR($A800),MONTH($A800),1),$A$5:$A$800,"<="&$A800)+IF(AND(YEAR($A800)=YEAR(Settings!$B$3),MONTH($A800)=MONTH(Settings!$B$3)),Settings!$B$12,0)) | Q800: =IF($A800="","",SUMIFS($I$5:$I$800,$A$5:$A$800,">="&DATE(YEAR($A800),MONTH($A800),1),$A$5:$A$800,"<="&$A800)+IF(AND(YEAR($A800)=YEAR(Settings!$B$3),MONTH($A800)=MONTH(Settings!$B$3)),Settings!$B$13,0)) | R800: =IF($A800="","",N800+P800) | S800: =IF($A800="","",O800+Q800)

Sheet Hours & Remarks
A1: BLOCK 4 – PLANT AND EQUIPMENT'S RUNNING HOURS/KM + BLOCK 6 – REMARKS (one row per day)
A2: Type everything in yellow: hours for each section/machine, Camper km, and a short remark for Primary and Secondary sections.
B3: 4. PLANT AND EQUIPMENT'S RUNNING HOURS/KM | F3: 6. REMARKS | H3: 4. KM
A4: Date | B4: Primary Section Hrs | C4: Secondary Section Hrs | D4: Hyundai Excavator R230 Hrs | E4: JCB UP92T7813 Hrs | F4: Remarks – Primary Section | G4: Remarks – Secondary Section | H4: Camper MP07ZM6345 km

Sheet Diesel
A1: BLOCK 5 – FUEL (DIESEL) (one row per day)
A2: Type litres received today for each vehicle (blank or 0 = none). Totals calculate.
A4: Date | B4: Camper MP07ZM6345 Ltr | C4: JCB UP92T7813 Ltr | D4: Hyundai Excavator R230 Ltr | E4: Total Diesel Received Today Ltr | F4: Total Diesel This Month Ltr
E5: =IF($A5="","",B5+C5+D5) | F5: =IF($A5="","",SUMIFS($E$5:$E$800,$A$5:$A$800,">="&DATE(YEAR($A5),MONTH($A5),1),$A$5:$A$800,"<="&$A5)+IF(AND(YEAR($A5)=YEAR(Settings!$B$3),MONTH($A5)=MONTH(Settings!$B$3)),Settings!$B$14,0))
E6: =IF($A6="","",B6+C6+D6) | F6: =IF($A6="","",SUMIFS($E$5:$E$800,$A$5:$A$800,">="&DATE(YEAR($A6),MONTH($A6),1),$A$5:$A$800,"<="&$A6)+IF(AND(YEAR($A6)=YEAR(Settings!$B$3),MONTH($A6)=MONTH(Settings!$B$3)),Settings!$B$14,0))
E7: =IF($A7="","",B7+C7+D7) | F7: =IF($A7="","",SUMIFS($E$5:$E$800,$A$5:$A$800,">="&DATE(YEAR($A7),MONTH($A7),1),$A$5:$A$800,"<="&$A7)+IF(AND(YEAR($A7)=YEAR(Settings!$B$3),MONTH($A7)=MONTH(Settings!$B$3)),Settings!$B$14,0))
E8: =IF($A8="","",B8+C8+D8) | F8: =IF($A8="","",SUMIFS($E$5:$E$800,$A$5:$A$800,">="&DATE(YEAR($A8),MONTH($A8),1),$A$5:$A$800,"<="&$A8)+IF(AND(YEAR($A8)=YEAR(Settings!$B$3),MONTH($A8)=MONTH(Settings!$B$3)),Settings!$B$14,0))
E9: =IF($A9="","",B9+C9+D9) | F9: =IF($A9="","",SUMIFS($E$5:$E$800,$A$5:$A$800,">="&DATE(YEAR($A9),MONTH($A9),1),$A$5:$A$800,"<="&$A9)+IF(AND(YEAR($A9)=YEAR(Settings!$B$3),MONTH($A9)=MONTH(Settings!$B$3)),Settings!$B$14,0))
E10: =IF($A10="","",B10+C10+D10) | F10: =IF($A10="","",SUMIFS($E$5:$E$800,$A$5:$A$800,">="&DATE(YEAR($A10),MONTH($A10),1),$A$5:$A$800,"<="&$A10)+IF(AND(YEAR($A10)=YEAR(Settings!$B$3),MONTH($A10)=MONTH(Settings!$B$3)),Settings!$B$14,0))
E11: =IF($A11="","",B11+C11+D11) | F11: =IF($A11="","",SUMIFS($E$5:$E$800,$A$5:$A$800,">="&DATE(YEAR($A11),MONTH($A11),1),$A$5:$A$800,"<="&$A11)+IF(AND(YEAR($A11)=YEAR(Settings!$B$3),MONTH($A11)=MONTH(Settings!$B$3)),Settings!$B$14,0))
E12: =IF($A12="","",B12+C12+D12) | F12: =IF($A12="","",SUMIFS($E$5:$E$800,$A$5:$A$800,">="&DATE(YEAR($A12),MONTH($A12),1),$A$5:$A$800,"<="&$A12)+IF(AND(YEAR($A12)=YEAR(Settings!$B$3),MONTH($A12)=MONTH(Settings!$B$3)),Settings!$B$14,0))
E13: =IF($A13="","",B13+C13+D13) | F13: =IF($A13="","",SUMIFS($E$5:$E$800,$A$5:$A$800,">="&DATE(YEAR($A13),MONTH($A13),1),$A$5:$A$800,"<="&$A13)+IF(AND(YEAR($A13)=YEAR(Settings!$B$3),MONTH($A13)=MONTH(Settings!$B$3)),Settings!$B$14,0))
E14: =IF($A14="","",B14+C14+D14) | F14: =IF($A14="","",SUMIFS($E$5:$E$800,$A$5:$A$800,">="&DATE(YEAR($A14),MONTH($A14),1),$A$5:$A$800,"<="&$A14)+IF(AND(YEAR($A14)=YEAR(Settings!$B$3),MONTH($A14)=MONTH(Settings!$B$3)),Settings!$B$14,0))
E15: =IF($A15="","",B15+C15+D15) | F15: =IF($A15="","",SUMIFS($E$5:$E$800,$A$5:$A$800,">="&DATE(YEAR($A15),MONTH($A15),1),$A$5:$A$800,"<="&$A15)+IF(AND(YEAR($A15)=YEAR(Settings!$B$3),MONTH($A15)=MONTH(Settings!$B$3)),Settings!$B$14,0))
E16: =IF($A16="","",B16+C16+D16) | F16: =IF($A16="","",SUMIFS($E$5:$E$800,$A$5:$A$800,">="&DATE(YEAR($A16),MONTH($A16),1),$A$5:$A$800,"<="&$A16)+IF(AND(YEAR($A16)=YEAR(Settings!$B$3),MONTH($A16)=MONTH(Settings!$B$3)),Settings!$B$14,0))
... E800: =IF($A800="","",B800+C800+D800) | F800: =IF($A800="","",SUMIFS($E$5:$E$800,$A$5:$A$800,">="&DATE(YEAR($A800),MONTH($A800),1),$A$5:$A$800,"<="&$A800)+IF(AND(YEAR($A800)=YEAR(Settings!$B$3),MONTH($A800)=MONTH(Settings!$B$3)),Settings!$B$14,0))

Sheet Settings
A1: SETTINGS – fill once when you start using this file
A3: Start date (first day entered) | B3: 46296 | C3: First row in the daily sheets: 01-10-2026.
A4: Boulder stock at start of first day (MT) | B4: 355 | C4: Back-calculated from the 01-10 report: closing 235 = opening + 100 to stock − 220 crushed from stock → opening 355.
A5: Starting avg MT per vehicle (report note) | B5: 20 | C5: Used for the report Note only until the first day with trips. After that the Note averages are worked out from MT ÷ trips.
A6: OPENING – Boulder received this month before start date (MT) | B6: 0 | C6: Start date is the 1st, so nothing before it this month.
A7: OPENING – Boulder received this month before start date (Trips) | B7: 0
A8: OPENING – Cumulative production before start date (MT) | B8: 67417.5 | C8: 01-10 report: 67882.320 cumulative − 464.820 received on 1st.
A9: OPENING – Cumulative production before start date (Trips) | B9: 2864 | C9: 2883 − 19.
A10: OPENING – Aggregate dispatch this month before start date (MT) | B10: 0
A11: OPENING – Aggregate dispatch this month before start date (Trips) | B11: 0
A12: OPENING – M-Sand dispatch this month before start date (MT) | B12: 0
A13: OPENING – M-Sand dispatch this month before start date (Trips) | B13: 0
A14: OPENING – Diesel this month before start date (Ltr) | B14: 0 | C14: Month diesel = sum of diesel received (confirmed by the reports: 294 → 625 → 900 → … → 2422).
A15: Prepared by | B15: Hemant Shukla | C15: Name printed at the bottom of the report.
A18: Legend:
A19: Yellow cells, blue text = you type
A20: Green cells, black text = formula (don't type)
A21: Opening values only apply to the start month; next month starts from zero. Cumulative never resets.

Sheet Chart Data
A1: Date | B1: Direct to Hopper | C1: Crushed from Stock | D1: Closing Stock | E1: 10 MM | F1: 20 MM | G1: 30 MM | H1: M-Sand | I1: Primary Section | J1: Secondary Section | K1: Diesel Received | M1: Material | N1: This Month MT | P1: Latest
A2: =Dashboard!$E$2-14 | B2: =SUMIFS('Daily Boulder'!$D$5:$D$800,'Daily Boulder'!$A$5:$A$800,$A2) | C2: =SUMIFS('Daily Boulder'!$F$5:$F$800,'Daily Boulder'!$A$5:$A$800,$A2) | D2: =SUMIFS('Daily Boulder'!$R$5:$R$800,'Daily Boulder'!$A$5:$A$800,$A2) | E2: =SUMIFS('Daily Dispatch'!$B$5:$B$800,'Daily Dispatch'!$A$5:$A$800,$A2) | F2: =SUMIFS('Daily Dispatch'!$D$5:$D$800,'Daily Dispatch'!$A$5:$A$800,$A2) | G2: =SUMIFS('Daily Dispatch'!$F$5:$F$800,'Daily Dispatch'!$A$5:$A$800,$A2) | H2: =SUMIFS('Daily Dispatch'!$H$5:$H$800,'Daily Dispatch'!$A$5:$A$800,$A2) | I2: =SUMIFS('Hours & Remarks'!$B$5:$B$800,'Hours & Remarks'!$A$5:$A$800,$A2) | J2: =SUMIFS('Hours & Remarks'!$C$5:$C$800,'Hours & Remarks'!$A$5:$A$800,$A2) | K2: =SUMIFS(Diesel!$E$5:$E$800,Diesel!$A$5:$A$800,$A2) | M2: Aggregate | N2: =IF(ISNUMBER(Dashboard!$G$17),Dashboard!$G$17,0) | P2: =IFERROR(TEXT(LARGE('Daily Boulder'!$A$5:$A$800,1),"dd-mmm-yyyy"),"")
A3: =Dashboard!$E$2-13 | B3: =SUMIFS('Daily Boulder'!$D$5:$D$800,'Daily Boulder'!$A$5:$A$800,$A3) | C3: =SUMIFS('Daily Boulder'!$F$5:$F$800,'Daily Boulder'!$A$5:$A$800,$A3) | D3: =SUMIFS('Daily Boulder'!$R$5:$R$800,'Daily Boulder'!$A$5:$A$800,$A3) | E3: =SUMIFS('Daily Dispatch'!$B$5:$B$800,'Daily Dispatch'!$A$5:$A$800,$A3) | F3: =SUMIFS('Daily Dispatch'!$D$5:$D$800,'Daily Dispatch'!$A$5:$A$800,$A3) | G3: =SUMIFS('Daily Dispatch'!$F$5:$F$800,'Daily Dispatch'!$A$5:$A$800,$A3) | H3: =SUMIFS('Daily Dispatch'!$H$5:$H$800,'Daily Dispatch'!$A$5:$A$800,$A3) | I3: =SUMIFS('Hours & Remarks'!$B$5:$B$800,'Hours & Remarks'!$A$5:$A$800,$A3) | J3: =SUMIFS('Hours & Remarks'!$C$5:$C$800,'Hours & Remarks'!$A$5:$A$800,$A3) | K3: =SUMIFS(Diesel!$E$5:$E$800,Diesel!$A$5:$A$800,$A3) | M3: M-Sand | N3: =IF(ISNUMBER(Dashboard!$G$18),Dashboard!$G$18,0) | P3: =IFERROR(TEXT(LARGE('Daily Boulder'!$A$5:$A$800,2),"dd-mmm-yyyy"),"")
A4: =Dashboard!$E$2-12 | B4: =SUMIFS('Daily Boulder'!$D$5:$D$800,'Daily Boulder'!$A$5:$A$800,$A4) | C4: =SUMIFS('Daily Boulder'!$F$5:$F$800,'Daily Boulder'!$A$5:$A$800,$A4) | D4: =SUMIFS('Daily Boulder'!$R$5:$R$800,'Daily Boulder'!$A$5:$A$800,$A4) | E4: =SUMIFS('Daily Dispatch'!$B$5:$B$800,'Daily Dispatch'!$A$5:$A$800,$A4) | F4: =SUMIFS('Daily Dispatch'!$D$5:$D$800,'Daily Dispatch'!$A$5:$A$800,$A4) | G4: =SUMIFS('Daily Dispatch'!$F$5:$F$800,'Daily Dispatch'!$A$5:$A$800,$A4) | H4: =SUMIFS('Daily Dispatch'!$H$5:$H$800,'Daily Dispatch'!$A$5:$A$800,$A4) | I4: =SUMIFS('Hours & Remarks'!$B$5:$B$800,'Hours & Remarks'!$A$5:$A$800,$A4) | J4: =SUMIFS('Hours & Remarks'!$C$5:$C$800,'Hours & Remarks'!$A$5:$A$800,$A4) | K4: =SUMIFS(Diesel!$E$5:$E$800,Diesel!$A$5:$A$800,$A4) | P4: =IFERROR(TEXT(LARGE('Daily Boulder'!$A$5:$A$800,3),"dd-mmm-yyyy"),"")
A5: =Dashboard!$E$2-11 | B5: =SUMIFS('Daily Boulder'!$D$5:$D$800,'Daily Boulder'!$A$5:$A$800,$A5) | C5: =SUMIFS('Daily Boulder'!$F$5:$F$800,'Daily Boulder'!$A$5:$A$800,$A5) | D5: =SUMIFS('Daily Boulder'!$R$5:$R$800,'Daily Boulder'!$A$5:$A$800,$A5) | E5: =SUMIFS('Daily Dispatch'!$B$5:$B$800,'Daily Dispatch'!$A$5:$A$800,$A5) | F5: =SUMIFS('Daily Dispatch'!$D$5:$D$800,'Daily Dispatch'!$A$5:$A$800,$A5) | G5: =SUMIFS('Daily Dispatch'!$F$5:$F$800,'Daily Dispatch'!$A$5:$A$800,$A5) | H5: =SUMIFS('Daily Dispatch'!$H$5:$H$800,'Daily Dispatch'!$A$5:$A$800,$A5) | I5: =SUMIFS('Hours & Remarks'!$B$5:$B$800,'Hours & Remarks'!$A$5:$A$800,$A5) | J5: =SUMIFS('Hours & Remarks'!$C$5:$C$800,'Hours & Remarks'!$A$5:$A$800,$A5) | K5: =SUMIFS(Diesel!$E$5:$E$800,Diesel!$A$5:$A$800,$A5) | P5: =IFERROR(TEXT(LARGE('Daily Boulder'!$A$5:$A$800,4),"dd-mmm-yyyy"),"")
A6: =Dashboard!$E$2-10 | B6: =SUMIFS('Daily Boulder'!$D$5:$D$800,'Daily Boulder'!$A$5:$A$800,$A6) | C6: =SUMIFS('Daily Boulder'!$F$5:$F$800,'Daily Boulder'!$A$5:$A$800,$A6) | D6: =SUMIFS('Daily Boulder'!$R$5:$R$800,'Daily Boulder'!$A$5:$A$800,$A6) | E6: =SUMIFS('Daily Dispatch'!$B$5:$B$800,'Daily Dispatch'!$A$5:$A$800,$A6) | F6: =SUMIFS('Daily Dispatch'!$D$5:$D$800,'Daily Dispatch'!$A$5:$A$800,$A6) | G6: =SUMIFS('Daily Dispatch'!$F$5:$F$800,'Daily Dispatch'!$A$5:$A$800,$A6) | H6: =SUMIFS('Daily Dispatch'!$H$5:$H$800,'Daily Dispatch'!$A$5:$A$800,$A6) | I6: =SUMIFS('Hours & Remarks'!$B$5:$B$800,'Hours & Remarks'!$A$5:$A$800,$A6) | J6: =SUMIFS('Hours & Remarks'!$C$5:$C$800,'Hours & Remarks'!$A$5:$A$800,$A6) | K6: =SUMIFS(Diesel!$E$5:$E$800,Diesel!$A$5:$A$800,$A6) | P6: =IFERROR(TEXT(LARGE('Daily Boulder'!$A$5:$A$800,5),"dd-mmm-yyyy"),"")
A7: =Dashboard!$E$2-9 | B7: =SUMIFS('Daily Boulder'!$D$5:$D$800,'Daily Boulder'!$A$5:$A$800,$A7) | C7: =SUMIFS('Daily Boulder'!$F$5:$F$800,'Daily Boulder'!$A$5:$A$800,$A7) | D7: =SUMIFS('Daily Boulder'!$R$5:$R$800,'Daily Boulder'!$A$5:$A$800,$A7) | E7: =SUMIFS('Daily Dispatch'!$B$5:$B$800,'Daily Dispatch'!$A$5:$A$800,$A7) | F7: =SUMIFS('Daily Dispatch'!$D$5:$D$800,'Daily Dispatch'!$A$5:$A$800,$A7) | G7: =SUMIFS('Daily Dispatch'!$F$5:$F$800,'Daily Dispatch'!$A$5:$A$800,$A7) | H7: =SUMIFS('Daily Dispatch'!$H$5:$H$800,'Daily Dispatch'!$A$5:$A$800,$A7) | I7: =SUMIFS('Hours & Remarks'!$B$5:$B$800,'Hours & Remarks'!$A$5:$A$800,$A7) | J7: =SUMIFS('Hours & Remarks'!$C$5:$C$800,'Hours & Remarks'!$A$5:$A$800,$A7) | K7: =SUMIFS(Diesel!$E$5:$E$800,Diesel!$A$5:$A$800,$A7) | P7: =IFERROR(TEXT(LARGE('Daily Boulder'!$A$5:$A$800,6),"dd-mmm-yyyy"),"")
A8: =Dashboard!$E$2-8 | B8: =SUMIFS('Daily Boulder'!$D$5:$D$800,'Daily Boulder'!$A$5:$A$800,$A8) | C8: =SUMIFS('Daily Boulder'!$F$5:$F$800,'Daily Boulder'!$A$5:$A$800,$A8) | D8: =SUMIFS('Daily Boulder'!$R$5:$R$800,'Daily Boulder'!$A$5:$A$800,$A8) | E8: =SUMIFS('Daily Dispatch'!$B$5:$B$800,'Daily Dispatch'!$A$5:$A$800,$A8) | F8: =SUMIFS('Daily Dispatch'!$D$5:$D$800,'Daily Dispatch'!$A$5:$A$800,$A8) | G8: =SUMIFS('Daily Dispatch'!$F$5:$F$800,'Daily Dispatch'!$A$5:$A$800,$A8) | H8: =SUMIFS('Daily Dispatch'!$H$5:$H$800,'Daily Dispatch'!$A$5:$A$800,$A8) | I8: =SUMIFS('Hours & Remarks'!$B$5:$B$800,'Hours & Remarks'!$A$5:$A$800,$A8) | J8: =SUMIFS('Hours & Remarks'!$C$5:$C$800,'Hours & Remarks'!$A$5:$A$800,$A8) | K8: =SUMIFS(Diesel!$E$5:$E$800,Diesel!$A$5:$A$800,$A8) | P8: =IFERROR(TEXT(LARGE('Daily Boulder'!$A$5:$A$800,7),"dd-mmm-yyyy"),"")
A9: =Dashboard!$E$2-7 | B9: =SUMIFS('Daily Boulder'!$D$5:$D$800,'Daily Boulder'!$A$5:$A$800,$A9) | C9: =SUMIFS('Daily Boulder'!$F$5:$F$800,'Daily Boulder'!$A$5:$A$800,$A9) | D9: =SUMIFS('Daily Boulder'!$R$5:$R$800,'Daily Boulder'!$A$5:$A$800,$A9) | E9: =SUMIFS('Daily Dispatch'!$B$5:$B$800,'Daily Dispatch'!$A$5:$A$800,$A9) | F9: =SUMIFS('Daily Dispatch'!$D$5:$D$800,'Daily Dispatch'!$A$5:$A$800,$A9) | G9: =SUMIFS('Daily Dispatch'!$F$5:$F$800,'Daily Dispatch'!$A$5:$A$800,$A9) | H9: =SUMIFS('Daily Dispatch'!$H$5:$H$800,'Daily Dispatch'!$A$5:$A$800,$A9) | I9: =SUMIFS('Hours & Remarks'!$B$5:$B$800,'Hours & Remarks'!$A$5:$A$800,$A9) | J9: =SUMIFS('Hours & Remarks'!$C$5:$C$800,'Hours & Remarks'!$A$5:$A$800,$A9) | K9: =SUMIFS(Diesel!$E$5:$E$800,Diesel!$A$5:$A$800,$A9) | P9: =IFERROR(TEXT(LARGE('Daily Boulder'!$A$5:$A$800,8),"dd-mmm-yyyy"),"")
A10: =Dashboard!$E$2-6 | B10: =SUMIFS('Daily Boulder'!$D$5:$D$800,'Daily Boulder'!$A$5:$A$800,$A10) | C10: =SUMIFS('Daily Boulder'!$F$5:$F$800,'Daily Boulder'!$A$5:$A$800,$A10) | D10: =SUMIFS('Daily Boulder'!$R$5:$R$800,'Daily Boulder'!$A$5:$A$800,$A10) | E10: =SUMIFS('Daily Dispatch'!$B$5:$B$800,'Daily Dispatch'!$A$5:$A$800,$A10) | F10: =SUMIFS('Daily Dispatch'!$D$5:$D$800,'Daily Dispatch'!$A$5:$A$800,$A10) | G10: =SUMIFS('Daily Dispatch'!$F$5:$F$800,'Daily Dispatch'!$A$5:$A$800,$A10) | H10: =SUMIFS('Daily Dispatch'!$H$5:$H$800,'Daily Dispatch'!$A$5:$A$800,$A10) | I10: =SUMIFS('Hours & Remarks'!$B$5:$B$800,'Hours & Remarks'!$A$5:$A$800,$A10) | J10: =SUMIFS('Hours & Remarks'!$C$5:$C$800,'Hours & Remarks'!$A$5:$A$800,$A10) | K10: =SUMIFS(Diesel!$E$5:$E$800,Diesel!$A$5:$A$800,$A10) | P10: =IFERROR(TEXT(LARGE('Daily Boulder'!$A$5:$A$800,9),"dd-mmm-yyyy"),"")
A11: =Dashboard!$E$2-5 | B11: =SUMIFS('Daily Boulder'!$D$5:$D$800,'Daily Boulder'!$A$5:$A$800,$A11) | C11: =SUMIFS('Daily Boulder'!$F$5:$F$800,'Daily Boulder'!$A$5:$A$800,$A11) | D11: =SUMIFS('Daily Boulder'!$R$5:$R$800,'Daily Boulder'!$A$5:$A$800,$A11) | E11: =SUMIFS('Daily Dispatch'!$B$5:$B$800,'Daily Dispatch'!$A$5:$A$800,$A11) | F11: =SUMIFS('Daily Dispatch'!$D$5:$D$800,'Daily Dispatch'!$A$5:$A$800,$A11) | G11: =SUMIFS('Daily Dispatch'!$F$5:$F$800,'Daily Dispatch'!$A$5:$A$800,$A11) | H11: =SUMIFS('Daily Dispatch'!$H$5:$H$800,'Daily Dispatch'!$A$5:$A$800,$A11) | I11: =SUMIFS('Hours & Remarks'!$B$5:$B$800,'Hours & Remarks'!$A$5:$A$800,$A11) | J11: =SUMIFS('Hours & Remarks'!$C$5:$C$800,'Hours & Remarks'!$A$5:$A$800,$A11) | K11: =SUMIFS(Diesel!$E$5:$E$800,Diesel!$A$5:$A$800,$A11) | P11: =IFERROR(TEXT(LARGE('Daily Boulder'!$A$5:$A$800,10),"dd-mmm-yyyy"),"")
A12: =Dashboard!$E$2-4 | B12: =SUMIFS('Daily Boulder'!$D$5:$D$800,'Daily Boulder'!$A$5:$A$800,$A12) | C12: =SUMIFS('Daily Boulder'!$F$5:$F$800,'Daily Boulder'!$A$5:$A$800,$A12) | D12: =SUMIFS('Daily Boulder'!$R$5:$R$800,'Daily Boulder'!$A$5:$A$800,$A12) | E12: =SUMIFS('Daily Dispatch'!$B$5:$B$800,'Daily Dispatch'!$A$5:$A$800,$A12) | F12: =SUMIFS('Daily Dispatch'!$D$5:$D$800,'Daily Dispatch'!$A$5:$A$800,$A12) | G12: =SUMIFS('Daily Dispatch'!$F$5:$F$800,'Daily Dispatch'!$A$5:$A$800,$A12) | H12: =SUMIFS('Daily Dispatch'!$H$5:$H$800,'Daily Dispatch'!$A$5:$A$800,$A12) | I12: =SUMIFS('Hours & Remarks'!$B$5:$B$800,'Hours & Remarks'!$A$5:$A$800,$A12) | J12: =SUMIFS('Hours & Remarks'!$C$5:$C$800,'Hours & Remarks'!$A$5:$A$800,$A12) | K12: =SUMIFS(Diesel!$E$5:$E$800,Diesel!$A$5:$A$800,$A12) | P12: =IFERROR(TEXT(LARGE('Daily Boulder'!$A$5:$A$800,11),"dd-mmm-yyyy"),"")
A13: =Dashboard!$E$2-3 | B13: =SUMIFS('Daily Boulder'!$D$5:$D$800,'Daily Boulder'!$A$5:$A$800,$A13) | C13: =SUMIFS('Daily Boulder'!$F$5:$F$800,'Daily Boulder'!$A$5:$A$800,$A13) | D13: =SUMIFS('Daily Boulder'!$R$5:$R$800,'Daily Boulder'!$A$5:$A$800,$A13) | E13: =SUMIFS('Daily Dispatch'!$B$5:$B$800,'Daily Dispatch'!$A$5:$A$800,$A13) | F13: =SUMIFS('Daily Dispatch'!$D$5:$D$800,'Daily Dispatch'!$A$5:$A$800,$A13) | G13: =SUMIFS('Daily Dispatch'!$F$5:$F$800,'Daily Dispatch'!$A$5:$A$800,$A13) | H13: =SUMIFS('Daily Dispatch'!$H$5:$H$800,'Daily Dispatch'!$A$5:$A$800,$A13) | I13: =SUMIFS('Hours & Remarks'!$B$5:$B$800,'Hours & Remarks'!$A$5:$A$800,$A13) | J13: =SUMIFS('Hours & Remarks'!$C$5:$C$800,'Hours & Remarks'!$A$5:$A$800,$A13) | K13: =SUMIFS(Diesel!$E$5:$E$800,Diesel!$A$5:$A$800,$A13) | P13: =IFERROR(TEXT(LARGE('Daily Boulder'!$A$5:$A$800,12),"dd-mmm-yyyy"),"")
A14: =Dashboard!$E$2-2 | B14: =SUMIFS('Daily Boulder'!$D$5:$D$800,'Daily Boulder'!$A$5:$A$800,$A14) | C14: =SUMIFS('Daily Boulder'!$F$5:$F$800,'Daily Boulder'!$A$5:$A$800,$A14) | D14: =SUMIFS('Daily Boulder'!$R$5:$R$800,'Daily Boulder'!$A$5:$A$800,$A14) | E14: =SUMIFS('Daily Dispatch'!$B$5:$B$800,'Daily Dispatch'!$A$5:$A$800,$A14) | F14: =SUMIFS('Daily Dispatch'!$D$5:$D$800,'Daily Dispatch'!$A$5:$A$800,$A14) | G14: =SUMIFS('Daily Dispatch'!$F$5:$F$800,'Daily Dispatch'!$A$5:$A$800,$A14) | H14: =SUMIFS('Daily Dispatch'!$H$5:$H$800,'Daily Dispatch'!$A$5:$A$800,$A14) | I14: =SUMIFS('Hours & Remarks'!$B$5:$B$800,'Hours & Remarks'!$A$5:$A$800,$A14) | J14: =SUMIFS('Hours & Remarks'!$C$5:$C$800,'Hours & Remarks'!$A$5:$A$800,$A14) | K14: =SUMIFS(Diesel!$E$5:$E$800,Diesel!$A$5:$A$800,$A14) | P14: =IFERROR(TEXT(LARGE('Daily Boulder'!$A$5:$A$800,13),"dd-mmm-yyyy"),"")
A15: =Dashboard!$E$2-1 | B15: =SUMIFS('Daily Boulder'!$D$5:$D$800,'Daily Boulder'!$A$5:$A$800,$A15) | C15: =SUMIFS('Daily Boulder'!$F$5:$F$800,'Daily Boulder'!$A$5:$A$800,$A15) | D15: =SUMIFS('Daily Boulder'!$R$5:$R$800,'Daily Boulder'!$A$5:$A$800,$A15) | E15: =SUMIFS('Daily Dispatch'!$B$5:$B$800,'Daily Dispatch'!$A$5:$A$800,$A15) | F15: =SUMIFS('Daily Dispatch'!$D$5:$D$800,'Daily Dispatch'!$A$5:$A$800,$A15) | G15: =SUMIFS('Daily Dispatch'!$F$5:$F$800,'Daily Dispatch'!$A$5:$A$800,$A15) | H15: =SUMIFS('Daily Dispatch'!$H$5:$H$800,'Daily Dispatch'!$A$5:$A$800,$A15) | I15: =SUMIFS('Hours & Remarks'!$B$5:$B$800,'Hours & Remarks'!$A$5:$A$800,$A15) | J15: =SUMIFS('Hours & Remarks'!$C$5:$C$800,'Hours & Remarks'!$A$5:$A$800,$A15) | K15: =SUMIFS(Diesel!$E$5:$E$800,Diesel!$A$5:$A$800,$A15) | P15: =IFERROR(TEXT(LARGE('Daily Boulder'!$A$5:$A$800,14),"dd-mmm-yyyy"),"")
A16: =Dashboard!$E$2-0 | B16: =SUMIFS('Daily Boulder'!$D$5:$D$800,'Daily Boulder'!$A$5:$A$800,$A16) | C16: =SUMIFS('Daily Boulder'!$F$5:$F$800,'Daily Boulder'!$A$5:$A$800,$A16) | D16: =SUMIFS('Daily Boulder'!$R$5:$R$800,'Daily Boulder'!$A$5:$A$800,$A16) | E16: =SUMIFS('Daily Dispatch'!$B$5:$B$800,'Daily Dispatch'!$A$5:$A$800,$A16) | F16: =SUMIFS('Daily Dispatch'!$D$5:$D$800,'Daily Dispatch'!$A$5:$A$800,$A16) | G16: =SUMIFS('Daily Dispatch'!$F$5:$F$800,'Daily Dispatch'!$A$5:$A$800,$A16) | H16: =SUMIFS('Daily Dispatch'!$H$5:$H$800,'Daily Dispatch'!$A$5:$A$800,$A16) | I16: =SUMIFS('Hours & Remarks'!$B$5:$B$800,'Hours & Remarks'!$A$5:$A$800,$A16) | J16: =SUMIFS('Hours & Remarks'!$C$5:$C$800,'Hours & Remarks'!$A$5:$A$800,$A16) | K16: =SUMIFS(Diesel!$E$5:$E$800,Diesel!$A$5:$A$800,$A16) | P16: =IFERROR(TEXT(LARGE('Daily Boulder'!$A$5:$A$800,15),"dd-mmm-yyyy"),"")
P17: =IFERROR(TEXT(LARGE('Daily Boulder'!$A$5:$A$800,16),"dd-mmm-yyyy"),"")
P18: =IFERROR(TEXT(LARGE('Daily Boulder'!$A$5:$A$800,17),"dd-mmm-yyyy"),"")
P19: =IFERROR(TEXT(LARGE('Daily Boulder'!$A$5:$A$800,18),"dd-mmm-yyyy"),"")
P20: =IFERROR(TEXT(LARGE('Daily Boulder'!$A$5:$A$800,19),"dd-mmm-yyyy"),"")
P21: =IFERROR(TEXT(LARGE('Daily Boulder'!$A$5:$A$800,20),"dd-mmm-yyyy"),"")
P22: =IFERROR(TEXT(LARGE('Daily Boulder'!$A$5:$A$800,21),"dd-mmm-yyyy"),"")
P23: =IFERROR(TEXT(LARGE('Daily Boulder'!$A$5:$A$800,22),"dd-mmm-yyyy"),"")
P24: =IFERROR(TEXT(LARGE('Daily Boulder'!$A$5:$A$800,23),"dd-mmm-yyyy"),"")
P25: =IFERROR(TEXT(LARGE('Daily Boulder'!$A$5:$A$800,24),"dd-mmm-yyyy"),"")
P26: =IFERROR(TEXT(LARGE('Daily Boulder'!$A$5:$A$800,25),"dd-mmm-yyyy"),"")
P27: =IFERROR(TEXT(LARGE('Daily Boulder'!$A$5:$A$800,26),"dd-mmm-yyyy"),"")
P28: =IFERROR(TEXT(LARGE('Daily Boulder'!$A$5:$A$800,27),"dd-mmm-yyyy"),"")
P29: =IFERROR(TEXT(LARGE('Daily Boulder'!$A$5:$A$800,28),"dd-mmm-yyyy"),"")
P30: =IFERROR(TEXT(LARGE('Daily Boulder'!$A$5:$A$800,29),"dd-mmm-yyyy"),"")
P31: =IFERROR(TEXT(LARGE('Daily Boulder'!$A$5:$A$800,30),"dd-mmm-yyyy"),"")
P32: =IFERROR(TEXT(LARGE('Daily Boulder'!$A$5:$A$800,31),"dd-mmm-yyyy"),"")
P33: =IFERROR(TEXT(LARGE('Daily Boulder'!$A$5:$A$800,32),"dd-mmm-yyyy"),"")
P34: =IFERROR(TEXT(LARGE('Daily Boulder'!$A$5:$A$800,33),"dd-mmm-yyyy"),"")
P35: =IFERROR(TEXT(LARGE('Daily Boulder'!$A$5:$A$800,34),"dd-mmm-yyyy"),"")
P36: =IFERROR(TEXT(LARGE('Daily Boulder'!$A$5:$A$800,35),"dd-mmm-yyyy"),"")
P37: =IFERROR(TEXT(LARGE('Daily Boulder'!$A$5:$A$800,36),"dd-mmm-yyyy"),"")
P38: =IFERROR(TEXT(LARGE('Daily Boulder'!$A$5:$A$800,37),"dd-mmm-yyyy"),"")
P39: =IFERROR(TEXT(LARGE('Daily Boulder'!$A$5:$A$800,38),"dd-mmm-yyyy"),"")
P40: =IFERROR(TEXT(LARGE('Daily Boulder'!$A$5:$A$800,39),"dd-mmm-yyyy"),"")
...
